<?xml version="1.0"?>
<robot name="Franka_panda">

	<link name="virtual_root"/>
  
  	<joint name="base_joint" type="fixed">
    		<parent link="virtual_root"/>
    		<child link="panda.panda_link0_0"/>
    		<origin xyz="0 0 0" rpy="0 0 0"/>
 	</joint>
 	 
	<link name="panda.panda_link0_0">
		<inertial>
			<origin xyz="-0.041018 -0.00014 0.049974" rpy="0.0 0.0 0.0" />
			<mass value="0.629769" />
			<inertia ixx="0.00315" ixy="8.2904e-07" ixz="0.00015" iyy="0.00388" iyz="8.2299e-06" izz="0.004285" />
		</inertial>
		<visual name="panda.panda_link0_0_visual">
			<origin xyz="0.0 0.0 0.0" rpy="0.0 0.0 0.0" />
			<geometry>
				<mesh filename="package://panda_description/meshes/visual/link0.dae" scale="1.0 1.0 1.0" />
			</geometry>
		</visual>
		<collision name="panda.panda_link0_0_collision">
			<origin xyz="0.0 0.0 0.0" rpy="0.0 0.0 0.0" />
			<geometry>
				<mesh filename="package://panda_description/meshes/collision/link0.stl" scale="1.0 1.0 1.0" />
			</geometry>
		</collision>
	</link>
	
	<joint name="panda.panda_joint1" type="revolute">
		<origin xyz="0.0 0.0 0.333" rpy="0.0 0.0 0.0" />
		<parent link="panda.panda_link0_0" />
		<child link="panda.panda_link1_0" />
		<axis xyz="0 0 1" />
		<dynamics damping="0.003" friction="0.0" />
		<limit lower="-2.9671" upper="2.9671" effort="87.0" velocity="2.5" />
	</joint>

	<link name="panda.panda_link1_0">
		<inertial>
			<origin xyz="0.003875 0.002081 -0.04762" rpy="0.0 0.0 0.0" />
			<mass value="4.970684" />
			<inertia ixx="0.70337" ixy="-0.000139" ixz="0.006772" iyy="0.70661" iyz="0.019169" izz="0.009117" />
		</inertial>
		<visual name="panda.panda_link1_0_visual">
			<origin xyz="0.0 0.0 0.0" rpy="0.0 0.0 0.0" />
			<geometry>
				<mesh filename="package://panda_description/meshes/visual/link1.dae" scale="1.0 1.0 1.0" />
			</geometry>
		</visual>
		<collision name="panda.panda_link1_0_collision">
			<origin xyz="0.0 0.0 0.0" rpy="0.0 0.0 0.0" />
			<geometry>
				<mesh filename="package://panda_description/meshes/collision/link1.stl" scale="1.0 1.0 1.0" />
			</geometry>
		</collision>
	</link>
	
	<joint name="panda.panda_joint2" type="revolute">
		<origin xyz="0.0 0.0 0.0" rpy="-1.5707963267948966 0.0 0.0" />
		<parent link="panda.panda_link1_0" />
		<child link="panda.panda_link2_0" />
		<axis xyz="0 0 1" />
		<dynamics damping="0.003" friction="0.0" />
		<limit lower="-1.8326" upper="1.8326" effort="87.0" velocity="2.5" />
	</joint>

	<link name="panda.panda_link2_0">
		<inertial>
			<origin xyz="-0.003141 -0.02872 0.003495" rpy="0.0 0.0 0.0" />
			<mass value="0.646926" />
			<inertia ixx="0.007962" ixy="-0.003925" ixz="0.010254" iyy="0.02811" iyz="0.000704" izz="0.025995" />
		</inertial>
		<visual name="panda.panda_link2_0_visual">
			<origin xyz="0.0 0.0 0.0" rpy="0.0 0.0 0.0" />
			<geometry>
				<mesh filename="package://panda_description/meshes/visual/link2.dae" scale="1.0 1.0 1.0" />
			</geometry>
		</visual>
		<collision name="panda.panda_link2_0_collision">
			<origin xyz="0.0 0.0 0.0" rpy="0.0 0.0 0.0" />
			<geometry>
				<mesh filename="package://panda_description/meshes/collision/link2.stl" scale="1.0 1.0 1.0" />
			</geometry>
		</collision>
	</link>

	<joint name="panda.panda_joint3" type="revolute">
		<origin xyz="0.0 -0.316 0.0" rpy="1.5707963267948966 0.0 0.0" />
		<parent link="panda.panda_link2_0" />
		<child link="panda.panda_link3_0" />
		<axis xyz="0 0 1" />
		<dynamics damping="0.003" friction="0.0" />
		<limit lower="-2.9671" upper="2.9671" effort="87.0" velocity="2.5" />
	</joint>

	<link name="panda.panda_link3_0">
		<inertial>
			<origin xyz="0.027518 0.039252 -0.066502" rpy="0.0 0.0 0.0" />
			<mass value="3.228604" />
			<inertia ixx="0.037242" ixy="-0.004761" ixz="-0.011396" iyy="0.036155" iyz="-0.012805" izz="0.01083" />
		</inertial>
		<visual name="panda.panda_link3_0_visual">
			<origin xyz="0.0 0.0 0.0" rpy="0.0 0.0 0.0" />
			<geometry>
				<mesh filename="package://panda_description/meshes/visual/link3.dae" scale="1.0 1.0 1.0" />
			</geometry>
		</visual>
		<collision name="panda.panda_link3_0_collision">
			<origin xyz="0.0 0.0 0.0" rpy="0.0 0.0 0.0" />
			<geometry>
				<mesh filename="package://panda_description/meshes/collision/link3.stl" scale="1.0 1.0 1.0" />
			</geometry>
		</collision>
	</link>

	<joint name="panda.panda_joint4" type="revolute">
		<origin xyz="0.0825 0.0 0.0" rpy="1.5707963267948966 0.0 0.0" />
		<parent link="panda.panda_link3_0" />
		<child link="panda.panda_link4_0" />
		<axis xyz="0 0 1" />
		<dynamics damping="0.003" friction="0.0" />
		<limit lower="-3.1416" upper="-0.4" effort="87.0" velocity="2.5" />
	</joint>

	<link name="panda.panda_link4_0">
		<inertial>
			<origin xyz="-0.05316999999999999 0.10441899999999997 0.027453999999999992" rpy="0.0 0.0 0.0" />
			<mass value="3.587895" />
			<inertia ixx="0.025853" ixy="0.007796" ixz="-0.001332" iyy="0.019552" iyz="0.008641" izz="0.028323" />
		</inertial>
		<visual name="panda.panda_link4_0_visual">
			<origin xyz="0.0 0.0 0.0" rpy="0.0 0.0 0.0" />
			<geometry>
				<mesh filename="package://panda_description/meshes/visual/link4.dae" scale="1.0 1.0 1.0" />
			</geometry>
		</visual>
		<collision name="panda.panda_link4_0_collision">
			<origin xyz="0.0 0.0 0.0" rpy="0.0 0.0 0.0" />
			<geometry>
				<mesh filename="package://panda_description/meshes/collision/link4.stl" scale="1.0 1.0 1.0" />
			</geometry>
		</collision>
	</link>

	<joint name="panda.panda_joint5" type="revolute">
		<origin xyz="-0.0825 0.384 0.0" rpy="-1.5707963267948966 0.0 0.0" />
		<parent link="panda.panda_link4_0" />
		<child link="panda.panda_link5_0" />
		<axis xyz="0 0 1" />
		<dynamics damping="0.003" friction="0.0" />
		<limit lower="-2.9671" upper="2.9671" effort="12.0" velocity="3.0" />
	</joint>

	<link name="panda.panda_link5_0">
		<inertial>
			<origin xyz="-0.011953 0.041065 -0.038437" rpy="0.0 0.0 0.0" />
			<mass value="1.225946" />
			<inertia ixx="0.035549" ixy="-0.002117" ixz="-0.004037" iyy="0.029474" iyz="0.000229" izz="0.008627" />
		</inertial>
		<visual name="panda.panda_link5_0_visual">
			<origin xyz="0.0 0.0 0.0" rpy="0.0 0.0 0.0" />
			<geometry>
				<mesh filename="package://panda_description/meshes/visual/link5.dae" scale="1.0 1.0 1.0" />
			</geometry>
		</visual>
		<collision name="panda.panda_link5_0_collision">
			<origin xyz="0.0 0.0 0.0" rpy="0.0 0.0 0.0" />
			<geometry>
				<mesh filename="package://panda_description/meshes/collision/link5.stl" scale="1.0 1.0 1.0" />
			</geometry>
		</collision>
	</link>

	<joint name="panda.panda_joint6" type="revolute">
		<origin xyz="0.0 0.0 0.0" rpy="1.5707963267948966 0.0 0.0" />
		<parent link="panda.panda_link5_0" />
		<child link="panda.panda_link6_0" />
		<axis xyz="0 0 1" />
		<dynamics damping="0.003" friction="0.0" />
		<limit lower="-0.0873" upper="3.8223" effort="12.0" velocity="3.0" />
	</joint>

	<link name="panda.panda_link6_0">
		<inertial>
			<origin xyz="0.060149 -0.014117 -0.010517" rpy="0.0 0.0 0.0" />
			<mass value="1.666555" />
			<inertia ixx="0.0019640000000000005" ixy="0.000109" ixz="-0.001158" iyy="0.004354" iyz="0.000341" izz="0.005433" />
		</inertial>
		<visual name="panda.panda_link6_0_visual">
			<origin xyz="0.0 0.0 0.0" rpy="0.0 0.0 0.0" />
			<geometry>
				<mesh filename="package://panda_description/meshes/visual/link6.dae" scale="1.0 1.0 1.0" />
			</geometry>
		</visual>
		<collision name="panda.panda_link6_0_collision">
			<origin xyz="0.0 0.0 0.0" rpy="0.0 0.0 0.0" />
			<geometry>
				<mesh filename="package://panda_description/meshes/collision/link6.stl" scale="1.0 1.0 1.0" />
			</geometry>
		</collision>
	</link>

	<joint name="panda.panda_joint7" type="revolute">
		<origin xyz="0.088 0.0 0.0" rpy="1.5707963267948966 0.0 0.0" />
		<parent link="panda.panda_link6_0" />
		<child link="panda.panda_link7_0" />
		<axis xyz="0 0 1" />
		<dynamics damping="0.003" friction="0.0" />
		<limit lower="-2.9671" upper="2.9671" effort="12.0" velocity="3.0" />
	</joint>

	<link name="panda.panda_link7_0">
		<inertial>
			<origin xyz="0.010517 -0.004252 0.061597" rpy="0.0 0.0 0.0" />
			<mass value="0.735522" />
			<inertia ixx="0.012516" ixy="-0.000428" ixz="-0.001196" iyy="0.010027" iyz="-0.000741" izz="0.004815" />
		</inertial>
		<visual name="panda.panda_link7_0_visual">
			<origin xyz="0.0 0.0 0.0" rpy="0.0 0.0 0.0" />
			<geometry>
				<mesh filename="package://panda_description/meshes/visual/link7.dae" scale="1.0 1.0 1.0" />
			</geometry>
		</visual>
		<collision name="panda.panda_link7_0_collision">
			<origin xyz="0.0 0.0 0.0" rpy="0.0 0.0 0.0" />
			<geometry>
				<mesh filename="package://panda_description/meshes/collision/link7.stl" scale="1.0 1.0 1.0" />
			</geometry>
		</collision>
	</link>

	<joint name="panda.panda_link7_0.panda_joint8" type="fixed">
		<origin xyz="0.0 0.0 0.107" rpy="0.0 0.0 0.0" />
		<parent link="panda.panda_link7_0" />
		<child link="panda.panda_link7_0.panda_joint8.body" />
	</joint>

	<link name="panda.panda_link7_0.panda_joint8.body" />
</robot>
